Workbook

Sheet Task Tracker
A1: PSUT LLM Engine - Phase 2 Project Task Breakdown
A2: # | B2: Task | C2: Description | D2: Est. Acc Days | E2: Assignee
A3: Milestone 1 - Requirements & Foundation · Weeks 1-6
A4: 1.1 | B4: Kick-off meeting and project charter | C4: Conduct internal kick-off with full team, define delivery scope, assign responsibilities, agree on communication cadence and sprint structure | D4: 4 | E4: Yazan Abu Osbeh
A5: 1.2 | B5: Stakeholder requirements gathering - eLearning department | C5: Meet with PSUT eLearning team to understand LMS structure, document management workflows, material publishing process, and API availability for integration | D5: 6 | E5: Yazan Abu Osbeh
A6: 1.3 | B6: Stakeholder requirements gathering - student portal IT | C6: Meet with PSUT portal IT team to understand portal architecture, available API endpoints, survey data structure, and report delivery and display requirements | D6: 4 | E6: Yazan Abu Osbeh
A7: 1.4 | B7: Stakeholder requirements gathering - student registration | C7: Meet with PSUT registration department to understand academic record data structure, data access method options, and semester data delivery process | D7: 4 | E7: Yazan Abu Osbeh
A8: 1.5 | B8: Stakeholder requirements gathering - academic governance | C8: Meet with PSUT academic governance team to understand compliance requirements, data privacy constraints, and report approval and sign-off process | D8: 4 | E8: Yazan Abu Osbeh
A9: 1.6 | B9: Requirements consolidation and sign-off | C9: Consolidate all stakeholder inputs into a unified requirements document, circulate for review, and obtain written sign-off from PSUT before development begins | D9: 4 | E9: Yazan Abu Osbeh
A10: 1.7 | B10: Sprint planning and milestone scheduling | C10: Break Phase 2 scope into sprints, assign tasks to team members, define milestone acceptance criteria, and set up internal progress tracking | D10: 4 | E10: Yazan Abu Osbeh
A11: 1.8 | B11: System architecture design | C11: Design full technical architecture for both subsystems , data flows, service boundaries, integration points, API contracts, infrastructure topology | D11: 8 | E11: Mahmoud Qaddoura
A12: 1.9 | B12: Architecture review and sign-off | C12: Review architecture design with team leads, incorporate feedback, and obtain internal sign-off before development begins | D12: 4 | E12: Mahmoud Qaddoura
A13: 1.10 | B13: Database schema design | C13: Design full PostgreSQL schema , users, courses, enrolments, chat sessions, messages, documents, document chunks, audit logs, report jobs, academic reports | D13: 6 | E13: Mahmoud Qaddoura
A14: 1.11 | B14: Database schema peer review | C14: Peer review schema design with fullstack engineer, finalise table relationships, confirm JSONB usage for report storage, validate indexing strategy | D14: 4 | E14: Mohammad Abzakh
A15: 1.12 | B15: FastAPI project scaffold and repository setup | C15: Initialise fresh repository, set up project directory structure , api, services, repositories, models, schemas, clients, utils, core , and configure linting and type checking | D15: 4 | E15: Mohammad Abzakh
... A26: 1.23 | B26: Documentation - development environment setup guide | C26: Write developer onboarding and environment setup guide covering repository structure, local environment setup, Docker usage, environment variables, and running the application locally. | D26: 4 | E26: Mohammad Abzakh
A27: Estimated Effort in Accumulated Work Days: 124 | Total Business days: 30
A28: Milestone 2 - AI Tutor Core · Weeks 6-16
A29: 2.1 | B29: PSUT LMS API client | C29: Implement async HTTP client wrapping PSUT LMS API , authentication headers, request construction, retry logic with exponential backoff, timeout handling, and error classification | D29: 8 | E29: Abed Al Qader Madi
A30: 2.2 | B30: LMS document sync service | C30: Implement poll or webhook handler for LMS document publish and update events, download file to local storage, trigger document indexing pipeline on receipt | D30: 10 | E30: Abed Al Qader Madi
A31: 2.3 | B31: Institutional data sync service | C31: Consume PSUT academic API or ingest structured data dump to sync courses, course sections, student enrolments, and instructor assignments on configurable semester-start schedule | D31: 10 | E31: Yehya Mujahid
A32: 2.4 | B32: APScheduler integration | C32: Configure APScheduler for document sync, institutional data sync, notification aggregation, and semester-start trigger jobs. Implement job monitoring and failure alerting | D32: 4 | E32: Mohammad Abzakh
A33: 2.5 | B33: Data access and API credential provisioning | C33: Receive, securely store, and validate all required credentials and API keys from PSUT , LMS API, academic data system, student portal , and verify connectivity to each | D33: 4 | E33: Lina Khalil
A34: 2.6 | B34: Document ingestion pipeline | C34: Implement file type detection, text extraction for PDF, DOCX, PPTX, and TXT formats, language detection, semantic chunking with configurable chunk size and overlap strategy | D34: 8 | E34: Mahmoud Qaddoura
A35: 2.7 | B35: Embedding pipeline | C35: Implement OpenAI text-embedding-3-small client with batch embedding support, upsert vectors to Qdrant with full metadata payload , document ID, chunk ID, course ID, semester, filename, hash | D35: 8 | E35: Mahmoud Qaddoura
A36: 2.8 | B36: RAG retrieval service | C36: Implement vector similarity search on Qdrant with course and semester metadata filters, top-k chunk retrieval, overlapping chunk deduplication, and relevance scoring | D36: 10 | E36: Abed Al Qader Madi
A37: 2.9 | B37: Prompt and context assembly service | C37: Implement system prompt builder, context window assembly from retrieved chunks, chat history injection, query normalisation, and token budget management | D37: 8 | E37: Mahmoud Qaddoura
A38: 2.10 | B38: OpenAI GPT-4.1 streaming client | C38: Implement async OpenAI client with streaming response support, SSE chunk wrapper, rate limit handling with retry, token usage tracking, and error classification | D38: 8 | E38: Yehya Mujahid
A39: 2.11 | B39: Chat session management | C39: Implement chat session creation, retrieval, and course-scoped session isolation. Handle session expiry, orphaned session cleanup, and concurrent session limits per user | D39: 8 | E39: Yehya Mujahid
A40: 2.12 | B40: Chat API endpoint | C40: Implement POST /chat with StreamingResponse, authentication and enrolment guard, session management integration, full RAG pipeline invocation, and SSE response streaming | D40: 4 | E40: Mohammad Abzakh
... A58: 2.30 | B58: Documentation - QA test plan and test results - AI Tutor | C58: Document test plan covering scope, test cases, pass/fail criteria, and environment setup. Append test execution results and any defects raised during AI Tutor testing. | D58: 4 | E58: Mahmoud Qaddoura
A59: Estimated Effort in Accumulated Work Days: 244 | Total Business days: 50
A60: Milestone 3 - Academic Advisor Core · Weeks 16-26
A61: 3.1 | B61: Academic data ingestion module - abstraction layer | C61: Implement abstract ingestion interface with common output schema supporting three interchangeable input methods , data dump, direct DB read, REST API , without requiring changes to downstream components | D61: 6 | E61: Abed Al Qader Madi
A62: 3.2 | B62: Data dump parser | C62: Implement parser for structured CSV or SQL dump of student academic records , completed courses, grades, GPA, credit hours, study plan, enrolment year, expected graduation , with validation and error reporting | D62: 6 | E62: Abed Al Qader Madi
A63: 3.3 | B63: Direct database read adapter | C63: Implement read-only SQLAlchemy connection to PSUT academic database, query student records across relevant tables, map to internal schema with field validation | D63: 8 | E63: Yehya Mujahid
A64: 3.4 | B64: PSUT academic API adapter | C64: Implement HTTP client for PSUT student data API with paginated fetch, response mapping to internal schema, error handling, and rate limit compliance | D64: 8 | E64: Yehya Mujahid
A65: 3.5 | B65: Student survey ingestion | C65: Consume end-of-semester student survey responses from PSUT portal API or structured export, validate response completeness, and persist per student per semester with linkage to academic record | D65: 6 | E65: Abed Al Qader Madi
A66: 3.6 | B66: Report job queue - table and worker base | C66: Create ReportJob table with status state machine , pending, in_progress, completed, failed, dead_letter. Implement SELECT FOR UPDATE SKIP LOCKED job claiming and worker base class with status transition methods | D66: 8 | E66: Yehya Mujahid
A67: 3.7 | B67: Parallel batch worker | C67: Implement two concurrent worker processes each independently claiming and processing jobs from the queue. Support configurable concurrency level and graceful shutdown on signal | D67: 8 | E67: Abed Al Qader Madi
...

Sheet Legend & Summary
A1: Project Legend & Workload Summary
A3: Colour Legend — Grouped by Role
A4: Milestone 1 — Requirements & Foundation
A5: Milestone 2 — AI Tutor Core
A6: Milestone 3 — Academic Advisor Core
A7: Milestone 4 — Integration, Testing & Deployment
A8: Yazan Abu Osbeh — Project Manager — Stakeholder coordination, project management, UAT, handover
A9: Mahmoud Qaddoura — Lead AI Engineer — Architecture, RAG pipeline, prompt engineering, fine-tuning
A10: Abed Al Qader Madi — AI Engineer — AI development tasks
A11: Yehya Mujahid — AI Full Stack Developer — AI development tasks
A12: Mohammad Abzakh — Full Stack Lead — Backend APIs, frontend
A13: Lina Khalil — Devops and Systems Engineer — deployment, DevOps, monitoring
... A17: Workload Summary of Effort Days and Business Days by Milestone
A18: Milestone | B18: Timeline | C18: Yazan (PM) | D18: Mahmoud (Lead AI) | E18: Abzakh (Fullstack Lead) | F18: Abed (AI Eng) | G18: Yehya (AI Dev) | H18: Lina (Devops) | I18: Balawi (Security & Devops lead)
A19: Milestone 1 — Requirements & Foundation | B19: Weeks 1–6 (30 B.D) | C19: =SUM('Task Tracker'!D4,'Task Tracker'!D5,'Task Tracker'!D6,'Task Tracker'!D7,'Task Tracker'!D8,'Task Tracker'!D9,'Task Tracker'!D10) -> 30 | D19: =SUM('Task Tracker'!D11,'Task Tracker'!D12,'Task Tracker'!D13,'Task Tracker'!D24,'Task Tracker'!D25) -> 30 | E19: =SUM('Task Tracker'!D14,'Task Tracker'!D15,'Task Tracker'!D19) -> 12 | F19: =SUM('Task Tracker'!D20,'Task Tracker'!D21) -> 14 | G19: =SUM('Task Tracker'!D22,'Task Tracker'!D23) -> 14 | H19: =SUM('Task Tracker'!D18) -> 6 | I19: =SUM('Task Tracker'!D16,'Task Tracker'!D17) -> 8
A20: Milestone 2 — AI Tutor Core | B20: Weeks 6–16 (50 B.D) | C20: 0 | D20: =SUM('Task Tracker'!D34,'Task Tracker'!D35,'Task Tracker'!D37,'Task Tracker'!D47,'Task Tracker'!D53,'Task Tracker'!D54,'Task Tracker'!D55,'Task Tracker'!D57,'Task Tracker'!D58) -> 48 | E20: =SUM('Task Tracker'!D32,'Task Tracker'!D40,'Task Tracker'!D41,'Task Tracker'!D48,'Task Tracker'!D49,'Task Tracker'!D51,'Task Tracker'!D56) -> 38 | F20: =SUM('Task Tracker'!D29,'Task Tracker'!D30,'Task Tracker'!D36,'Task Tracker'!D42,'Task Tracker'!D44,'Task Tracker'!D50) -> 50 | G20: =SUM('Task Tracker'!D31,'Task Tracker'!D38,'Task Tracker'!D39,'Task Tracker'!D43,'Task Tracker'!D46,'Task Tracker'!D45) -> 50 | H20: =SUM('Task Tracker'!D33,'Task Tracker'!D52) -> 12 | I20: 0
A21: Milestone 3 — Academic Advisor Core | B21: Weeks 16–26 (50 B.D) | C21: 0 | D21: =SUM('Task Tracker'!D73,'Task Tracker'!D79,'Task Tracker'!D81,'Task Tracker'!D82,'Task Tracker'!D83,'Task Tracker'!D84,'Task Tracker'!D86,'Task Tracker'!D87) -> 50 | E21: =SUM('Task Tracker'!D70,'Task Tracker'!D71,'Task Tracker'!D76,'Task Tracker'!D77,'Task Tracker'!D85) -> 36 | F21: =SUM('Task Tracker'!D61,'Task Tracker'!D62,'Task Tracker'!D65,'Task Tracker'!D67,'Task Tracker'!D69,'Task Tracker'!D74,'Task Tracker'!D80) -> 50 | G21: =SUM('Task Tracker'!D63,'Task Tracker'!D64,'Task Tracker'!D66,'Task Tracker'!D68,'Task Tracker'!D72,'Task Tracker'!D75,'Task Tracker'!D78) -> 50 | H21: 0 | I21: 0
A22: Milestone 4 — Integration, Testing & Deployment | B22: Weeks 26–34 (40 B.D) | C22: =SUM('Task Tracker'!D110,'Task Tracker'!D109,'Task Tracker'!D103,'Task Tracker'!D102) -> 28 | D22: =SUM('Task Tracker'!D92,'Task Tracker'!D106) -> 16 | E22: =SUM('Task Tracker'!D96) -> 8 | F22: 0 | G22: 0 | H22: =SUM('Task Tracker'!D90,'Task Tracker'!D91,'Task Tracker'!D97,'Task Tracker'!D99,'Task Tracker'!D100,'Task Tracker'!D104,'Task Tracker'!D108) -> 40 | I22: =SUM('Task Tracker'!D107,'Task Tracker'!D105,'Task Tracker'!D101,'Task Tracker'!D98,'Task Tracker'!D95,'Task Tracker'!D94,'Task Tracker'!D93) -> 40
A23: TOTAL Effort | B23: ~34 Weeks / 8 Months | C23: =SUM(C19:C22) -> 58 | D23: =SUM(D19:D22) -> 144 | E23: =SUM(E19:E22) -> 94 | F23: =SUM(F19:F22) -> 114 | G23: =SUM(G19:G22) -> 114 | H23: =SUM(H19:H22) -> 58 | I23: =SUM(I19:I22) -> 48
A24: Hourly Rate | B24: JoD/Hour | C24: 8 | D24: 6 | E24: 6 | F24: 4 | G24: 4 | H24: 4 | I24: 6
A25: TOTAL Reimbursement Rounded | B25: Total Cost = Total Days × 8 × Hourly Rate × 1.20 | C25: =C23*8*C24*1.2 -> 4454.4 | D25: =D23*8*D24*1.2 -> 8294.4 | E25: =E23*8*E24*1.2 -> 5414.4 | F25: =F23*8*F24*1.2 -> 4377.6 | G25: =G23*8*G24*1.2 -> 4377.6 | H25: =H23*8*H24*1.2 -> 2227.2 | I25: =I23*8*I24*1.2 -> 2764.8
